# 相关问题

### 1、设计脚本时，尽量不要与npm自带的脚本重名，不然会出现死循环。

---

### 2、Promise中的then、catch、finally

- Promise的状态一经改变就不能再改变了。

```js
const promise = new Promise((resolve, reject) => {
  resolve("success1");
  reject("error");
  resolve("success2");
});
promise
.then(res => {
    console.log("then: ", res);
  }).catch(err => {
    console.log("catch: ", err);
  })
// then：success1
```



- then和catch都会返回一个新的Promise。
- catch不管被连接到哪里，都能捕获上层未捕捉过的错误。

```js
const promise = new Promise((resolve, reject) => {
  reject("error");
  resolve("success2");
});
promise
.then(res => {
    console.log("then1: ", res);
  }).then(res => {
    console.log("then2: ", res);
  }).catch(err => {
    console.log("catch: ", err);
  }).then(res => {
    console.log("then3: ", res);
  })
 
//"catch: " "error"  验证第三点的总结
//"then3: " undefined  验证第二点总结
```



- 在Promise中，返回任意一个非Promise的值都会被包裹成Promise对象。
- Promise的.then或者.catch可以被调用多次，但如果Promise内部的状态一经改变，并且有了一个值，那么后续的每次调用.then或者.catch的时候都会拿到该值。

```js
const promise = new Promise((resolve, reject) => {
  setTimeout(() => {
    console.log('timer')
    resolve('success')
  }, 1000)
})
const start = Date.now();
promise.then(res => {
  console.log(res, Date.now() - start)
})
promise.then(res => {
  console.log(res, Date.now() - start)
})
 
//'timer'
//'success' 1001
//'success' 1002
// Promise 的 .then 或者 .catch 可以被调用多次，但这里 Promise 构造函数只执行一次。
// 或者说 promise 内部状态一经改变，并且有了一个值，那么后续每次调用 .then 或者 .catch 都会直接拿到该值。
```



- .then或者.catch中return一个error对象并不会抛出错误，所以不会被后续的.catch捕获。

```js
Promise.resolve().then(() => {
  return new Error('error!!!')
}).then(res => {
  console.log("then: ", res)
}).catch(err => {
  console.log("catch: ", err)
})
 
//"then: " "Error: error!!!"
 
// 这验证了第4点和第6点，返回任意一个非 promise 的值都会被包裹成 promise 对象，
// 因此这里的return new Error('error!!!')也被包裹成了return Promise.resolve(new Error('error!!!'))。
```

<span style='color:red'>抛出错误的方式</span>

```js
return Promise.reject(new Error('error!!!'));
// or
throw new Error('error!!!')
```

- .then或者.catch返回的值不能是Promise本身，否则会造成死循环。
- .then或者.catch的参数期望是函数，传入非函数则会发生值透传。

```js
Promise.resolve(1)
  .then(2)
  .then(Promise.resolve(3))
  .then(console.log)
 
// 1
// 第一个then和第二个then中传入的都不是函数，一个是数字类型，一个是对象类型
// 因此发生了透传，将resolve(1) 的值直接传到最后一个then里。
```

- .then方法是能接收两个参数，第一个是处理成功的函数，第二个是处理失败的函数，在一些 时候可以认为catch是.then第二个参数的简便写法。
- .finally方法也是返回一个Promise，在Promise结束的时候，无论结果为resolved还是rejected，都会执行里面的回调函数。
  - .finally方法不管Promise对象最后的状态如何都会执行。
  - .finally方法的回调函数不接受任何的参数，在这个方法中，无法得知Promise最终的状态是resolved函数rejected
  - 它最终返回的默认会是一个上一次的Promise对象值，不过如果抛出的是一个异常则返回异常的Promise对象。
